Workbook

Sheet Data
A1: Device | B1: Metric (Group A) | C1: Metric (Group B) | E1: Предположим, что у нас пользователи могут заходить на сайт с двух типов устройств: компьютер (PC) или мобильный телефон (mobile). Мы проводим рекламную компанию, и под успехом понимаем факт захода на сайт.
A2: PC | B2: 0 | C2: 0 | E2: 1) Посчитаем статистики контрольной и тестовой группах
A3: PC | B3: 0 | C3: 0 | F3: Group A | I3: Group B
A4: PC | B4: 0 | C4: 0 | F4: PC | G4: MOBILE | H4: ALL | I4: PC | J4: MOBILE | K4: ALL
A5: PC | B5: 0 | C5: 1 | E5: пользователей | F5: =COUNTIF($A$2:$A$101,"PC") -> 44 | G5: =COUNTIF($A$2:$A$101,"mobile") -> 56 | H5: =SUM(F5:G5) -> 100 | I5: =COUNTIF($A$2:$A$101,"PC") -> 44 | J5: =COUNTIF($A$2:$A$101,"mobile") -> 56 | K5: =SUM(I5:J5) -> 100 | M5: 44000 | N5: 56000
A6: PC | B6: 0 | C6: 0 | E6: успехов | F6: =SUMIF($A$2:$A$101,"PC",$B$2:$B$101) -> 7 | G6: =SUMIF($A$2:$A$101,"mobile",$B$2:$B$101) -> 41 | H6: =SUM(F6:G6) -> 48 | I6: =SUMIF($A$2:$A$101,"PC",$C$2:$C$101) -> 10 | J6: =SUMIF($A$2:$A$101,"mobile",$C$2:$C$101) -> 47 | K6: =SUM(I6:J6) -> 57
A7: PC | B7: 0 | C7: 0 | E7: доля успехов | F7: =F6/F5 -> 0.15909091 | G7: =G6/G5 -> 0.73214286 | H7: =H6/H5 -> 0.48 | I7: =I6/I5 -> 0.22727273 | J7: =J6/J5 -> 0.83928571 | K7: =K6/K5 -> 0.57
A8: PC | B8: 1 | C8: 0 | M8: B | N8: A
A9: PC | B9: 0 | C9: 0 | E9: 2) На вкладке (SRS index) заранее сгенерированные случайные индексы элементов для бутстреп процедуры | M9: 35 PC | N9: 52 PC | P9: 0
A10: PC | B10: 0 | C10: 0 | E10: 3) Построим гистограмму числа пользователей PC в случайном семпле (ширина бина 2 единицы) | M10: 65 ios | N10: 48 ios | P10: 0.1
A11: PC | B11: 0 | C11: 1 | M11: 6.5 | N11: 4.8 | O11: =M11-N11 -> 1.7
A12: PC | B12: 0 | C12: 0
A13: PC | B13: 0 | C13: 0
A14: PC | B14: 0 | C14: 1
A15: PC | B15: 0 | C15: 0
A16: PC | B16: 1 | C16: 0
A17: PC | B17: 0 | C17: 0
A18: PC | B18: 0 | C18: 1
A19: PC | B19: 0 | C19: 0
A20: PC | B20: 0 | C20: 0
A21: PC | B21: 0 | C21: 0
A22: PC | B22: 0 | C22: 1
A23: PC | B23: 0 | C23: 0 | E23: Мы видим, что при случайном семплировании размеры страт могут сильно отличаться от истинных значений
A24: PC | B24: 1 | C24: 0 | E24: Позже мы увидим, насколько негативно эти отклонения сказываются на дисперсии и научимся с этим бороться
A25: PC | B25: 0 | C25: 0
A26: PC | B26: 0 | C26: 0
A27: PC | B27: 0 | C27: 1
A28: PC | B28: 0 | C28: 0
A29: PC | B29: 1 | C29: 0
A30: PC | B30: 0 | C30: 0
A31: PC | B31: 0 | C31: 1
A32: PC | B32: 0 | C32: 0
A33: PC | B33: 0 | C33: 0
A34: PC | B34: 1 | C34: 0
A35: PC | B35: 0 | C35: 0
A36: PC | B36: 0 | C36: 0
... A101: mobile | B101: 1 | C101: 1

Sheet Variance Comparison
A1: 1) Проще всего провести процедуру простого семплирования (SRS). Мы можем реализовать уже знакомый нам бутстреп. Метрика считается как простое среднее. Бутстреп процедура реализована на странице post-stratification
A2: Metric SRS (A) = | B2: ='post-stratification'!B1 -> 0.45 | C2: ='post-stratification'!C1 -> 0.43 | D2: ='post-stratification'!D1 -> 0.53 | E2: ='post-stratification'!E1 -> 0.56 | F2: ='post-stratification'!F1 -> 0.52 | G2: ='post-stratification'!G1 -> 0.47 | H2: ='post-stratification'!H1 -> 0.55 | I2: ='post-stratification'!I1 -> 0.46 | ... CW2: ='post-stratification'!CW1 -> 0.49
A3: Metric SRS (B) = | B3: ='post-stratification'!B107 -> 0.54 | C3: ='post-stratification'!C107 -> 0.56 | D3: ='post-stratification'!D107 -> 0.52 | E3: ='post-stratification'!E107 -> 0.67 | F3: ='post-stratification'!F107 -> 0.61 | G3: ='post-stratification'!G107 -> 0.55 | H3: ='post-stratification'!H107 -> 0.49 | I3: ='post-stratification'!I107 -> 0.62 | ... CW3: ='post-stratification'!CW107 -> 0.55
A4: Delta SRS = | B4: =B3-B2 -> 0.09 | C4: =C3-C2 -> 0.13 | D4: =D3-D2 -> -0.01 | E4: =E3-E2 -> 0.11 | F4: =F3-F2 -> 0.09 | G4: =G3-G2 -> 0.08 | H4: =H3-H2 -> -0.06 | I4: =I3-I2 -> 0.16 | ... CW4: =CW3-CW2 -> 0.06
A5: посчитаем среднее значение статистики (разность средних) и среднеквадратичное отклонение для неё
B6: Real Delta = | E6: =Data!K7-Data!H7 -> 0.09 | G6: Std Delta SRS = | J6: =_xlfn.STDEV.S(B4:CW4) -> 0.06752478
B7: CI= | C7: 0.9 | D7: Z= | E7: =_xlfn.NORM.S.INV(1 - (1-C7)/2) -> 1.6448536 | F7: left= | H7: =E6 - E7*J6 -> -0.02106838 | J7: right= | L7: =E6 + E7 * J6 -> 0.20106838 | N7: =IF(H7*L7<0,"FAIL","OK!") -> FAIL
A8: Получился очень большой разброс, что приводит к неудаче в эксперименте. Надо снижать дисперсию!
A10: 2) На тех же данных посчитаем постстратификацию. Единственное отличие – способ подсчета среднего. Вместо обычного среднего подсчитаем стратифицированное среднее
A11: Metric Post (A) = | B11: ='post-stratification'!B4 -> 0.47339744 | C11: ='post-stratification'!C4 -> 0.45025641 | D11: ='post-stratification'!D4 -> 0.48912913 | E11: ='post-stratification'!E4 -> 0.55425541 | F11: ='post-stratification'!F4 -> 0.50100041 | G11: ='post-stratification'!G4 -> 0.50913165 | H11: ='post-stratification'!H4 -> 0.52947499 | I11: ='post-stratification'!I4 -> 0.46979066 | ... CW11: ='post-stratification'!CW4 -> 0.46
A12: Metric Post (B) = | B12: ='post-stratification'!B110 -> 0.49201201 | C12: ='post-stratification'!C110 -> 0.52108659 | D12: ='post-stratification'!D110 -> 0.54296919 | E12: ='post-stratification'!E110 -> 0.63317487 | F12: ='post-stratification'!F110 -> 0.61 | G12: ='post-stratification'!G110 -> 0.56231884 | H12: ='post-stratification'!H110 -> 0.50090177 | I12: ='post-stratification'!I110 -> 0.64365385 | ... CW12: ='post-stratification'!CW110 -> 0.53760263
A13: Delta Post = | B13: =B12-B11 -> 0.018614576 | C13: =C12-C11 -> 0.070830177 | D13: =D12-D11 -> 0.053840059 | E13: =E12-E11 -> 0.078919467 | F13: =F12-F11 -> 0.10899959 | G13: =G12-G11 -> 0.053187188 | H13: =H12-H11 -> -0.028573218 | I13: =I12-I11 -> 0.17386319 | ... CW13: =CW12-CW11 -> 0.077602627
B14: Real Delta = | E14: =Data!K7-Data!H7 -> 0.09 | G14: Std Delta Post = | J14: =_xlfn.STDEV.S(B13:CW13) -> 0.054899432
B15: CI= | C15: 0.9 | D15: Z= | E15: =_xlfn.NORM.S.INV(1 - (1-C15)/2) -> 1.6448536 | F15: left= | H15: =E14 - E15*J14 -> -0.00030152977 | J15: right= | L15: =E14 + E15 * J14 -> 0.18030153 | N15: =IF(H15*L15<0,"FAIL","OK!") -> FAIL
A16: Мы видим, что доверительный интервал существенно сузился, хотя тест по прежнему не проходит. Но уже мы в пограничном случае.
A18: 3) Но можно рассмотреть процедуру, которая обеспечивает ещё меньший разброс в данных: стратифицированное семплирование. Мы должны выбирать число представителей каждого класса пропорционально числу представителей этого класса среди генеральной совокупности наших пользователей. Как и в предыдущем случае считаем взвешенное среднее.
A20: Metric StratS (A) = | B20: =stratification!B4 -> 0.46 | C20: =stratification!C4 -> 0.54 | D20: =stratification!D4 -> 0.45 | E20: =stratification!E4 -> 0.47 | F20: =stratification!F4 -> 0.51 | G20: =stratification!G4 -> 0.52 | H20: =stratification!H4 -> 0.43 | I20: =stratification!I4 -> 0.51 | ... CW20: =stratification!CW4 -> 0.45
A21: Metric StratS (B) = | B21: =stratification!B110 -> 0.63 | C21: =stratification!C110 -> 0.61 | D21: =stratification!D110 -> 0.57 | E21: =stratification!E110 -> 0.57 | F21: =stratification!F110 -> 0.54 | G21: =stratification!G110 -> 0.57 | H21: =stratification!H110 -> 0.57 | I21: =stratification!I110 -> 0.58 | ... CW21: =stratification!CW110 -> 0.6
A22: Delta StratS = | B22: =B21-B20 -> 0.17 | C22: =C21-C20 -> 0.07 | D22: =D21-D20 -> 0.12 | E22: =E21-E20 -> 0.1 | F22: =F21-F20 -> 0.03 | G22: =G21-G20 -> 0.05 | H22: =H21-H20 -> 0.14 | I22: =I21-I20 -> 0.07 | ... CW22: =CW21-CW20 -> 0.15
B23: Real Delta = | E23: =Data!K7-Data!H7 -> 0.09 | G23: Std Delta Post = | J23: =_xlfn.STDEV.S(B22:CW22) -> 0.052261966
B24: CI= | C24: 0.9 | D24: Z= | E24: =_xlfn.NORM.S.INV(1 - (1-C24)/2) -> 1.6448536 | F24: left= | H24: =E23 - E24*J23 -> 0.004036715 | J24: right= | L24: =E23 + E24 * J23 -> 0.17596328 | N24: =IF(H24*L24<0,"FAIL","OK!") -> OK!
A25: Мы видим, что процедура стратификации сильнее всего снижает дисперсию! Если при проведении эксперимента у вас есть возможность провести стратификацию - не пренебрегайте ей.

Sheet (SRS index)
A1: =COUNTIF(A3:A102,"<=44") -> 48 | B1: =COUNTIF(B3:B102,"<=44") -> 48 | C1: =COUNTIF(C3:C102,"<=44") -> 37 | D1: =COUNTIF(D3:D102,"<=44") -> 43 | E1: =COUNTIF(E3:E102,"<=44") -> 41 | F1: =COUNTIF(F3:F102,"<=44") -> 51 | G1: =COUNTIF(G3:G102,"<=44") -> 41 | H1: =COUNTIF(H3:H102,"<=44") -> 46 | ... CV1: =COUNTIF(CV3:CV102,"<=44") -> 36
A2: Group A index | K2: Group A index | U2: Group A index | AE2: Group A index | AO2: Group A index | AY2: Group A index | BI2: Group A index | BS2: Group A index | CC2: Group A index | CM2: Group A index
A3: 87 | B3: 72 | C3: 51 | D3: 67 | E3: 69 | F3: 99 | G3: 65 | H3: 69 | I3: 81 | J3: 27 | K3: 30 | L3: 28 | M3: 13 | N3: 38 | O3: 2 | P3: 47 | Q3: 1 | R3: 59 | S3: 17 | T3: 66 | U3: 17 | V3: 33 | W3: 56 | X3: 44 | Y3: 82 | Z3: 83 | AA3: 75 | AB3: 63 | AC3: 63 | AD3: 13 | AE3: 27 | AF3: 92 | AG3: 89 | AH3: 97 | AI3: 39 | AJ3: 66 | AK3: 53 | AL3: 12 | AM3: 96 | AN3: 30 | AO3: 32 | AP3: 57 | AQ3: 65 | AR3: 97 | AS3: 89 | AT3: 13 | AU3: 32 | AV3: 72 | AW3: 2 | AX3: 88 | AY3: 10 | AZ3: 81 | BA3: 48 | BB3: 28 | BC3: 13 | BD3: 100 | BE3: 89 | BF3: 27 | BG3: 74 | BH3: 98 | BI3: 38 | BJ3: 89 | BK3: 88 | BL3: 35 | BM3: 93 | BN3: 70 | BO3: 17 | BP3: 22 | BQ3: 42 | BR3: 43 | BS3: 91 | BT3: 1 | BU3: 75 | BV3: 81 | BW3: 32 | BX3: 51 | BY3: 28 | BZ3: 3 | CA3: 39 | CB3: 80 | CC3: 30 | CD3: 25 | CE3: 3 | CF3: 45 | CG3: 87 | CH3: 59 | CI3: 79 | CJ3: 59 | CK3: 67 | CL3: 34 | CM3: 89 | CN3: 20 | CO3: 21 | CP3: 63 | CQ3: 84 | CR3: 33 | CS3: 11 | CT3: 16 | CU3: 34 | CV3: 57
A4: 39 | B4: 29 | C4: 45 | D4: 2 | E4: 11 | F4: 70 | G4: 25 | H4: 28 | I4: 39 | J4: 35 | K4: 93 | L4: 88 | M4: 57 | N4: 24 | O4: 71 | P4: 78 | Q4: 2 | R4: 6 | S4: 74 | T4: 57 | U4: 19 | V4: 31 | W4: 58 | X4: 79 | Y4: 14 | Z4: 29 | AA4: 20 | AB4: 29 | AC4: 68 | AD4: 57 | AE4: 5 | AF4: 35 | AG4: 94 | AH4: 37 | AI4: 69 | AJ4: 95 | AK4: 72 | AL4: 30 | AM4: 44 | AN4: 69 | AO4: 6 | AP4: 16 | AQ4: 59 | AR4: 97 | AS4: 75 | AT4: 1 | AU4: 73 | AV4: 72 | AW4: 99 | AX4: 32 | AY4: 1 | AZ4: 73 | BA4: 83 | BB4: 89 | BC4: 19 | BD4: 39 | BE4: 31 | BF4: 39 | BG4: 88 | BH4: 86 | BI4: 46 | BJ4: 81 | BK4: 62 | BL4: 60 | BM4: 100 | BN4: 61 | BO4: 74 | BP4: 88 | BQ4: 4 | BR4: 65 | BS4: 91 | BT4: 75 | BU4: 11 | BV4: 28 | BW4: 94 | BX4: 23 | BY4: 63 | BZ4: 75 | CA4: 4 | CB4: 26 | CC4: 26 | CD4: 76 | CE4: 26 | CF4: 83 | CG4: 52 | CH4: 36 | CI4: 51 | CJ4: 85 | CK4: 30 | CL4: 89 | CM4: 69 | CN4: 23 | CO4: 72 | CP4: 36 | CQ4: 37 | CR4: 72 | CS4: 81 | CT4: 82 | CU4: 60 | CV4: 93
A5: 27 | B5: 65 | C5: 85 | D5: 91 | E5: 41 | F5: 100 | G5: 85 | H5: 25 | I5: 98 | J5: 72 | K5: 79 | L5: 18 | M5: 44 | N5: 73 | O5: 31 | P5: 4 | Q5: 37 | R5: 17 | S5: 84 | T5: 42 | U5: 83 | V5: 70 | W5: 40 | X5: 27 | Y5: 34 | Z5: 1 | AA5: 37 | AB5: 40 | AC5: 93 | AD5: 1 | AE5: 44 | AF5: 3 | AG5: 78 | AH5: 29 | AI5: 53 | AJ5: 72 | AK5: 94 | AL5: 20 | AM5: 95 | AN5: 29 | AO5: 59 | AP5: 22 | AQ5: 48 | AR5: 22 | AS5: 48 | AT5: 98 | AU5: 64 | AV5: 94 | AW5: 83 | AX5: 53 | AY5: 81 | AZ5: 18 | BA5: 69 | BB5: 14 | BC5: 29 | BD5: 42 | BE5: 30 | BF5: 19 | BG5: 52 | BH5: 78 | BI5: 25 | BJ5: 16 | BK5: 94 | BL5: 40 | BM5: 59 | BN5: 61 | BO5: 39 | BP5: 7 | BQ5: 60 | BR5: 61 | BS5: 77 | BT5: 46 | BU5: 57 | BV5: 6 | BW5: 2 | BX5: 65 | BY5: 95 | BZ5: 57 | CA5: 70 | CB5: 57 | CC5: 65 | CD5: 57 | CE5: 97 | CF5: 79 | CG5: 73 | CH5: 97 | CI5: 24 | CJ5: 24 | CK5: 18 | CL5: 96 | CM5: 9 | CN5: 28 | CO5: 9 | CP5: 53 | CQ5: 97 | CR5: 62 | CS5: 99 | CT5: 96 | CU5: 13 | CV5: 66
A6: 50 | B6: 97 | C6: 7 | D6: 15 | E6: 95 | F6: 50 | G6: 43 | H6: 95 | I6: 7 | J6: 6 | K6: 25 | L6: 51 | M6: 67 | N6: 14 | O6: 74 | P6: 78 | Q6: 57 | R6: 66 | S6: 15 | T6: 6 | U6: 85 | V6: 46 | W6: 29 | X6: 54 | Y6: 31 | Z6: 52 | AA6: 49 | AB6: 86 | AC6: 52 | AD6: 38 | AE6: 36 | AF6: 7 | AG6: 95 | AH6: 40 | AI6: 95 | AJ6: 71 | AK6: 75 | AL6: 15 | AM6: 74 | AN6: 21 | AO6: 61 | AP6: 61 | AQ6: 4 | AR6: 45 | AS6: 28 | AT6: 56 | AU6: 23 | AV6: 68 | AW6: 18 | AX6: 75 | AY6: 93 | AZ6: 70 | BA6: 51 | BB6: 100 | BC6: 35 | BD6: 68 | BE6: 90 | BF6: 38 | BG6: 78 | BH6: 66 | BI6: 35 | BJ6: 1 | BK6: 40 | BL6: 13 | BM6: 75 | BN6: 44 | BO6: 87 | BP6: 85 | BQ6: 74 | BR6: 31 | BS6: 48 | BT6: 78 | BU6: 64 | BV6: 53 | BW6: 99 | BX6: 82 | BY6: 34 | BZ6: 63 | CA6: 67 | CB6: 78 | CC6: 59 | CD6: 60 | CE6: 96 | CF6: 20 | CG6: 15 | CH6: 74 | CI6: 30 | CJ6: 42 | CK6: 45 | CL6: 5 | CM6: 63 | CN6: 42 | CO6: 5 | CP6: 74 | CQ6: 6 | CR6: 2 | CS6: 59 | CT6: 13 | CU6: 15 | CV6: 76
A7: 2 | B7: 57 | C7: 67 | D7: 67 | E7: 53 | F7: 23 | G7: 9 | H7: 62 | I7: 83 | J7: 51 | K7: 44 | L7: 66 | M7: 47 | N7: 52 | O7: 84 | P7: 14 | Q7: 13 | R7: 56 | S7: 50 | T7: 39 | U7: 72 | V7: 54 | W7: 55 | X7: 10 | Y7: 53 | Z7: 93 | AA7: 99 | AB7: 45 | AC7: 64 | AD7: 68 | AE7: 28 | AF7: 50 | AG7: 29 | AH7: 69 | AI7: 8 | AJ7: 32 | AK7: 61 | AL7: 32 | AM7: 64 | AN7: 52 | AO7: 31 | AP7: 39 | AQ7: 31 | AR7: 34 | AS7: 66 | AT7: 19 | AU7: 75 | AV7: 23 | AW7: 46 | AX7: 5 | AY7: 7 | AZ7: 19 | BA7: 67 | BB7: 97 | BC7: 30 | BD7: 96 | BE7: 96 | BF7: 28 | BG7: 61 | BH7: 4 | BI7: 33 | BJ7: 44 | BK7: 10 | BL7: 15 | BM7: 79 | BN7: 73 | BO7: 83 | BP7: 62 | BQ7: 70 | BR7: 12 | BS7: 32 | BT7: 34 | BU7: 79 | BV7: 91 | BW7: 26 | BX7: 19 | BY7: 72 | BZ7: 2 | CA7: 9 | CB7: 37 | CC7: 81 | CD7: 48 | CE7: 89 | CF7: 20 | CG7: 18 | CH7: 69 | CI7: 6 | CJ7: 84 | CK7: 12 | CL7: 76 | CM7: 35 | CN7: 46 | CO7: 92 | CP7: 56 | CQ7: 67 | CR7: 39 | CS7: 77 | CT7: 9 | CU7: 25 | CV7: 60
A8: 51 | B8: 56 | C8: 32 | D8: 76 | E8: 72 | F8: 41 | G8: 1 | H8: 90 | I8: 53 | J8: 28 | K8: 58 | L8: 91 | M8: 8 | N8: 19 | O8: 42 | P8: 51 | Q8: 37 | R8: 85 | S8: 1 | T8: 68 | U8: 13 | V8: 15 | W8: 45 | X8: 63 | Y8: 62 | Z8: 20 | AA8: 8 | AB8: 53 | AC8: 81 | AD8: 37 | AE8: 91 | AF8: 52 | AG8: 49 | AH8: 96 | AI8: 8 | AJ8: 60 | AK8: 85 | AL8: 82 | AM8: 12 | AN8: 70 | AO8: 99 | AP8: 63 | AQ8: 27 | AR8: 71 | AS8: 75 | AT8: 15 | AU8: 60 | AV8: 61 | AW8: 59 | AX8: 4 | AY8: 51 | AZ8: 13 | BA8: 16 | BB8: 68 | BC8: 17 | BD8: 21 | BE8: 81 | BF8: 29 | BG8: 36 | BH8: 18 | BI8: 8 | BJ8: 39 | BK8: 79 | BL8: 3 | BM8: 25 | BN8: 60 | BO8: 98 | BP8: 82 | BQ8: 33 | BR8: 51 | BS8: 1 | BT8: 77 | BU8: 27 | BV8: 90 | BW8: 46 | BX8: 76 | BY8: 72 | BZ8: 59 | CA8: 1 | CB8: 54 | CC8: 70 | CD8: 25 | CE8: 37 | CF8: 40 | CG8: 77 | CH8: 96 | CI8: 82 | CJ8: 65 | CK8: 22 | CL8: 77 | CM8: 9 | CN8: 43 | CO8: 63 | CP8: 88 | CQ8: 83 | CR8: 39 | CS8: 50 | CT8: 96 | CU8: 43 | CV8: 74
A9: 54 | B9: 57 | C9: 81 | D9: 46 | E9: 35 | F9: 74 | G9: 97 | H9: 79 | I9: 72 | J9: 8 | K9: 59 | L9: 78 | M9: 92 | N9: 9 | O9: 65 | P9: 59 | Q9: 26 | R9: 40 | S9: 86 | T9: 6 | U9: 96 | V9: 43 | W9: 81 | X9: 95 | Y9: 25 | Z9: 98 | AA9: 63 | AB9: 33 | AC9: 11 | AD9: 99 | AE9: 50 | AF9: 56 | AG9: 30 | AH9: 28 | AI9: 73 | AJ9: 27 | AK9: 1 | AL9: 55 | AM9: 76 | AN9: 2 | AO9: 82 | AP9: 25 | AQ9: 54 | AR9: 100 | AS9: 28 | AT9: 69 | AU9: 98 | AV9: 27 | AW9: 73 | AX9: 14 | AY9: 59 | AZ9: 58 | BA9: 53 | BB9: 97 | BC9: 52 | BD9: 35 | BE9: 99 | BF9: 23 | BG9: 6 | BH9: 93 | BI9: 85 | BJ9: 14 | BK9: 14 | BL9: 21 | BM9: 25 | BN9: 91 | BO9: 58 | BP9: 38 | BQ9: 8 | BR9: 54 | BS9: 62 | BT9: 24 | BU9: 9 | BV9: 82 | BW9: 69 | BX9: 96 | BY9: 58 | BZ9: 97 | CA9: 16 | CB9: 83 | CC9: 28 | CD9: 66 | CE9: 45 | CF9: 53 | CG9: 78 | CH9: 67 | CI9: 1 | CJ9: 46 | CK9: 20 | CL9: 91 | CM9: 67 | CN9: 44 | CO9: 37 | CP9: 9 | CQ9: 85 | CR9: 57 | CS9: 25 | CT9: 74 | CU9: 25 | CV9: 47
A10: 79 | B10: 8 | C10: 14 | D10: 76 | E10: 82 | F10: 7 | G10: 99 | H10: 24 | I10: 52 | J10: 51 | K10: 31 | L10: 81 | M10: 96 | N10: 45 | O10: 4 | P10: 86 | Q10: 61 | R10: 60 | S10: 82 | T10: 13 | U10: 76 | V10: 3 | W10: 88 | X10: 78 | Y10: 60 | Z10: 19 | AA10: 99 | AB10: 8 | AC10: 58 | AD10: 87 | AE10: 80 | AF10: 17 | AG10: 45 | AH10: 46 | AI10: 29 | AJ10: 49 | AK10: 64 | AL10: 8 | AM10: 60 | AN10: 26 | AO10: 25 | AP10: 10 | AQ10: 91 | AR10: 62 | AS10: 41 | AT10: 53 | AU10: 81 | AV10: 87 | AW10: 24 | AX10: 71 | AY10: 93 | AZ10: 52 | BA10: 21 | BB10: 8 | BC10: 29 | BD10: 11 | BE10: 30 | BF10: 34 | BG10: 75 | BH10: 45 | BI10: 33 | BJ10: 67 | BK10: 56 | BL10: 59 | BM10: 43 | BN10: 9 | BO10: 3 | BP10: 77 | BQ10: 62 | BR10: 35 | BS10: 84 | BT10: 91 | BU10: 93 | BV10: 87 | BW10: 11 | BX10: 15 | BY10: 58 | BZ10: 90 | CA10: 75 | CB10: 72 | CC10: 64 | CD10: 26 | CE10: 60 | CF10: 69 | CG10: 75 | CH10: 29 | CI10: 85 | CJ10: 23 | CK10: 41 | CL10: 42 | CM10: 30 | CN10: 69 | CO10: 24 | CP10: 97 | CQ10: 79 | CR10: 11 | CS10: 82 | CT10: 51 | CU10: 54 | CV10: 70
A11: 32 | B11: 28 | C11: 25 | D11: 23 | E11: 60 | F11: 55 | G11: 10 | H11: 55 | I11: 23 | J11: 10 | K11: 20 | L11: 58 | M11: 38 | N11: 71 | O11: 15 | P11: 95 | Q11: 83 | R11: 48 | S11: 12 | T11: 12 | U11: 4 | V11: 57 | W11: 47 | X11: 90 | Y11: 77 | Z11: 12 | AA11: 1 | AB11: 35 | AC11: 76 | AD11: 78 | AE11: 63 | AF11: 58 | AG11: 86 | AH11: 38 | AI11: 65 | AJ11: 94 | AK11: 21 | AL11: 27 | AM11: 45 | AN11: 13 | AO11: 98 | AP11: 82 | AQ11: 86 | AR11: 65 | AS11: 6 | AT11: 49 | AU11: 85 | AV11: 21 | AW11: 33 | AX11: 12 | AY11: 60 | AZ11: 70 | BA11: 19 | BB11: 94 | BC11: 83 | BD11: 63 | BE11: 43 | BF11: 41 | BG11: 20 | BH11: 4 | BI11: 71 | BJ11: 94 | BK11: 4 | BL11: 14 | BM11: 70 | BN11: 39 | BO11: 14 | BP11: 31 | BQ11: 88 | BR11: 83 | BS11: 58 | BT11: 27 | BU11: 63 | BV11: 92 | BW11: 7 | BX11: 83 | BY11: 91 | BZ11: 22 | CA11: 17 | CB11: 77 | CC11: 19 | CD11: 66 | CE11: 5 | CF11: 16 | CG11: 11 | CH11: 96 | CI11: 10 | CJ11: 86 | CK11: 21 | CL11: 26 | CM11: 2 | CN11: 55 | CO11: 46 | CP11: 63 | CQ11: 86 | CR11: 80 | CS11: 95 | CT11: 92 | CU11: 45 | CV11: 71
A12: 53 | B12: 30 | C12: 79 | D12: 68 | E12: 76 | F12: 28 | G12: 53 | H12: 90 | I12: 51 | J12: 47 | K12: 68 | L12: 70 | M12: 1 | N12: 47 | O12: 4 | P12: 71 | Q12: 9 | R12: 98 | S12: 92 | T12: 81 | U12: 56 | V12: 60 | W12: 60 | X12: 67 | Y12: 35 | Z12: 70 | AA12: 55 | AB12: 69 | AC12: 52 | AD12: 9 | AE12: 99 | AF12: 90 | AG12: 93 | AH12: 76 | AI12: 22 | AJ12: 29 | AK12: 89 | AL12: 37 | AM12: 29 | AN12: 99 | AO12: 45 | AP12: 87 | AQ12: 45 | AR12: 1 | AS12: 62 | AT12: 85 | AU12: 85 | AV12: 77 | AW12: 26 | AX12: 98 | AY12: 48 | AZ12: 11 | BA12: 34 | BB12: 20 | BC12: 64 | BD12: 97 | BE12: 46 | BF12: 93 | BG12: 81 | BH12: 1 | BI12: 62 | BJ12: 42 | BK12: 59 | BL12: 80 | BM12: 28 | BN12: 28 | BO12: 25 | BP12: 19 | BQ12: 28 | BR12: 73 | BS12: 71 | BT12: 74 | BU12: 55 | BV12: 25 | BW12: 99 | BX12: 70 | BY12: 32 | BZ12: 89 | CA12: 45 | CB12: 94 | CC12: 55 | CD12: 98 | CE12: 45 | CF12: 33 | CG12: 88 | CH12: 33 | CI12: 72 | CJ12: 11 | CK12: 69 | CL12: 89 | CM12: 26 | CN12: 77 | CO12: 76 | CP12: 93 | CQ12: 89 | CR12: 81 | CS12: 6 | CT12: 58 | CU12: 35 | CV12: 7
A13: 84 | B13: 44 | C13: 24 | D13: 22 | E13: 60 | F13: 69 | G13: 1 | H13: 19 | I13: 97 | J13: 51 | K13: 53 | L13: 3 | M13: 66 | N13: 74 | O13: 33 | P13: 8 | Q13: 9 | R13: 15 | S13: 95 | T13: 67 | U13: 90 | V13: 65 | W13: 52 | X13: 81 | Y13: 26 | Z13: 2 | AA13: 52 | AB13: 51 | AC13: 59 | AD13: 49 | AE13: 100 | AF13: 36 | AG13: 100 | AH13: 88 | AI13: 96 | AJ13: 78 | AK13: 18 | AL13: 68 | AM13: 28 | AN13: 51 | AO13: 5 | AP13: 52 | AQ13: 73 | AR13: 77 | AS13: 75 | AT13: 64 | AU13: 60 | AV13: 67 | AW13: 45 | AX13: 89 | AY13: 88 | AZ13: 59 | BA13: 44 | BB13: 14 | BC13: 17 | BD13: 81 | BE13: 4 | BF13: 4 | BG13: 99 | BH13: 70 | BI13: 1 | BJ13: 69 | BK13: 91 | BL13: 24 | BM13: 73 | BN13: 44 | BO13: 31 | BP13: 33 | BQ13: 52 | BR13: 44 | BS13: 19 | BT13: 63 | BU13: 62 | BV13: 73 | BW13: 43 | BX13: 9 | BY13: 90 | BZ13: 31 | CA13: 17 | CB13: 58 | CC13: 93 | CD13: 48 | CE13: 55 | CF13: 15 | CG13: 66 | CH13: 14 | CI13: 59 | CJ13: 43 | CK13: 45 | CL13: 41 | CM13: 46 | CN13: 68 | CO13: 88 | CP13: 18 | CQ13: 83 | CR13: 88 | CS13: 66 | CT13: 100 | CU13: 69 | CV13: 59
A14: 25 | B14: 92 | C14: 16 | D14: 33 | E14: 40 | F14: 43 | G14: 67 | H14: 37 | I14: 65 | J14: 21 | K14: 12 | L14: 51 | M14: 33 | N14: 29 | O14: 78 | P14: 4 | Q14: 38 | R14: 54 | S14: 73 | T14: 75 | U14: 17 | V14: 96 | W14: 49 | X14: 96 | Y14: 72 | Z14: 99 | AA14: 34 | AB14: 69 | AC14: 73 | AD14: 27 | AE14: 77 | AF14: 67 | AG14: 98 | AH14: 44 | AI14: 46 | AJ14: 53 | AK14: 62 | AL14: 37 | AM14: 46 | AN14: 73 | AO14: 82 | AP14: 42 | AQ14: 95 | AR14: 73 | AS14: 26 | AT14: 17 | AU14: 10 | AV14: 94 | AW14: 98 | AX14: 16 | AY14: 72 | AZ14: 73 | BA14: 32 | BB14: 79 | BC14: 40 | BD14: 12 | BE14: 98 | BF14: 85 | BG14: 16 | BH14: 95 | BI14: 75 | BJ14: 38 | BK14: 25 | BL14: 96 | BM14: 25 | BN14: 83 | BO14: 48 | BP14: 17 | BQ14: 99 | BR14: 68 | BS14: 45 | BT14: 83 | BU14: 35 | BV14: 91 | BW14: 60 | BX14: 47 | BY14: 87 | BZ14: 63 | CA14: 69 | CB14: 36 | CC14: 8 | CD14: 64 | CE14: 21 | CF14: 17 | CG14: 54 | CH14: 16 | CI14: 17 | CJ14: 3 | CK14: 55 | CL14: 43 | CM14: 79 | CN14: 68 | CO14: 1 | CP14: 56 | CQ14: 69 | CR14: 17 | CS14: 92 | CT14: 14 | CU14: 87 | CV14: 54
... A102: 71 | B102: 15 | C102: 51 | D102: 9 | E102: 82 | F102: 74 | G102: 91 | H102: 4 | I102: 18 | J102: 87 | K102: 17 | L102: 94 | M102: 22 | N102: 60 | O102: 81 | P102: 51 | Q102: 22 | R102: 25 | S102: 7 | T102: 32 | U102: 100 | V102: 98 | W102: 33 | X102: 99 | Y102: 71 | Z102: 14 | AA102: 90 | AB102: 27 | AC102: 26 | AD102: 86 | AE102: 66 | AF102: 74 | AG102: 80 | AH102: 33 | AI102: 13 | AJ102: 39 | AK102: 91 | AL102: 38 | AM102: 25 | AN102: 74 | AO102: 79 | AP102: 77 | AQ102: 71 | AR102: 92 | AS102: 15 | AT102: 69 | AU102: 3 | AV102: 30 | AW102: 17 | AX102: 7 | AY102: 69 | AZ102: 56 | BA102: 90 | BB102: 21 | BC102: 35 | BD102: 36 | BE102: 21 | BF102: 88 | BG102: 3 | BH102: 23 | BI102: 58 | BJ102: 78 | BK102: 67 | BL102: 81 | BM102: 63 | BN102: 84 | BO102: 67 | BP102: 74 | BQ102: 24 | BR102: 72 | BS102: 97 | BT102: 20 | BU102: 2 | BV102: 16 | BW102: 81 | BX102: 31 | BY102: 50 | BZ102: 48 | CA102: 64 | CB102: 78 | CC102: 88 | CD102: 57 | CE102: 70 | CF102: 33 | CG102: 54 | CH102: 86 | CI102: 72 | CJ102: 43 | CK102: 10 | CL102: 91 | CM102: 36 | CN102: 82 | CO102: 32 | CP102: 99 | CQ102: 72 | CR102: 26 | CS102: 37 | CT102: 23 | CU102: 57 | CV102: 19
A104: =COUNTIF(A106:A205,"<=44") -> 37 | B104: =COUNTIF(B106:B205,"<=44") -> 38 | C104: =COUNTIF(C106:C205,"<=44") -> 49 | D104: =COUNTIF(D106:D205,"<=44") -> 38 | E104: =COUNTIF(E106:E205,"<=44") -> 44 | F104: =COUNTIF(F106:F205,"<=44") -> 46 | G104: =COUNTIF(G106:G205,"<=44") -> 46 | H104: =COUNTIF(H106:H205,"<=44") -> 48 | ... CV104: =COUNTIF(CV106:CV205,"<=44") -> 42
A105: Group B index | K105: Group B index | U105: Group B index | AE105: Group B index | AO105: Group B index | AY105: Group B index | BI105: Group B index | BS105: Group B index | CC105: Group B index | CM105: Group B index
A106: 94 | B106: 88 | C106: 4 | D106: 67 | E106: 74 | F106: 65 | G106: 89 | H106: 17 | I106: 88 | J106: 43 | K106: 65 | L106: 49 | M106: 24 | N106: 60 | O106: 72 | P106: 22 | Q106: 61 | R106: 70 | S106: 21 | T106: 45 | U106: 52 | V106: 1 | W106: 54 | X106: 49 | Y106: 25 | Z106: 9 | AA106: 51 | AB106: 81 | AC106: 63 | AD106: 61 | AE106: 46 | AF106: 47 | AG106: 12 | AH106: 19 | AI106: 90 | AJ106: 88 | AK106: 68 | AL106: 53 | AM106: 20 | AN106: 4 | AO106: 85 | AP106: 54 | AQ106: 76 | AR106: 6 | AS106: 64 | AT106: 75 | AU106: 23 | AV106: 21 | AW106: 72 | AX106: 71 | AY106: 10 | AZ106: 48 | BA106: 48 | BB106: 21 | BC106: 59 | BD106: 6 | BE106: 6 | BF106: 93 | BG106: 64 | BH106: 36 | BI106: 90 | BJ106: 91 | BK106: 25 | BL106: 40 | BM106: 21 | BN106: 58 | BO106: 58 | BP106: 37 | BQ106: 76 | BR106: 84 | BS106: 59 | BT106: 51 | BU106: 23 | BV106: 66 | BW106: 16 | BX106: 70 | BY106: 23 | BZ106: 77 | CA106: 23 | CB106: 20 | CC106: 64 | CD106: 52 | CE106: 39 | CF106: 96 | CG106: 70 | CH106: 80 | CI106: 57 | CJ106: 7 | CK106: 31 | CL106: 21 | CM106: 16 | CN106: 90 | CO106: 10 | CP106: 16 | CQ106: 14 | CR106: 28 | CS106: 82 | CT106: 37 | CU106: 75 | CV106: 40
A107: 89 | B107: 92 | C107: 24 | D107: 56 | E107: 73 | F107: 51 | G107: 41 | H107: 84 | I107: 85 | J107: 10 | K107: 32 | L107: 95 | M107: 90 | N107: 68 | O107: 29 | P107: 15 | Q107: 61 | R107: 3 | S107: 60 | T107: 35 | U107: 80 | V107: 63 | W107: 82 | X107: 23 | Y107: 66 | Z107: 58 | AA107: 69 | AB107: 53 | AC107: 87 | AD107: 90 | AE107: 10 | AF107: 2 | AG107: 2 | AH107: 80 | AI107: 52 | AJ107: 66 | AK107: 77 | AL107: 34 | AM107: 60 | AN107: 40 | AO107: 42 | AP107: 1 | AQ107: 22 | AR107: 20 | AS107: 15 | AT107: 79 | AU107: 69 | AV107: 67 | AW107: 67 | AX107: 6 | AY107: 78 | AZ107: 58 | BA107: 10 | BB107: 87 | BC107: 25 | BD107: 26 | BE107: 49 | BF107: 89 | BG107: 32 | BH107: 70 | BI107: 96 | BJ107: 1 | BK107: 43 | BL107: 39 | BM107: 30 | BN107: 9 | BO107: 41 | BP107: 35 | BQ107: 92 | BR107: 34 | BS107: 82 | BT107: 51 | BU107: 51 | BV107: 65 | BW107: 14 | BX107: 2 | BY107: 92 | BZ107: 14 | CA107: 39 | CB107: 26 | CC107: 64 | CD107: 58 | CE107: 65 | CF107: 73 | CG107: 49 | CH107: 3 | CI107: 99 | CJ107: 58 | CK107: 97 | CL107: 28 | CM107: 35 | CN107: 13 | CO107: 67 | CP107: 62 | CQ107: 75 | CR107: 92 | CS107: 53 | CT107: 30 | CU107: 50 | CV107: 83
A108: 10 | B108: 27 | C108: 16 | D108: 67 | E108: 11 | F108: 55 | G108: 60 | H108: 76 | I108: 76 | J108: 21 | K108: 45 | L108: 78 | M108: 10 | N108: 58 | O108: 17 | P108: 56 | Q108: 91 | R108: 54 | S108: 98 | T108: 91 | U108: 92 | V108: 68 | W108: 67 | X108: 62 | Y108: 68 | Z108: 68 | AA108: 13 | AB108: 89 | AC108: 47 | AD108: 42 | AE108: 25 | AF108: 66 | AG108: 83 | AH108: 23 | AI108: 68 | AJ108: 49 | AK108: 12 | AL108: 93 | AM108: 88 | AN108: 36 | AO108: 72 | AP108: 2 | AQ108: 4 | AR108: 86 | AS108: 26 | AT108: 60 | AU108: 29 | AV108: 46 | AW108: 48 | AX108: 51 | AY108: 60 | AZ108: 74 | BA108: 25 | BB108: 73 | BC108: 95 | BD108: 25 | BE108: 20 | BF108: 95 | BG108: 37 | BH108: 44 | BI108: 27 | BJ108: 96 | BK108: 56 | BL108: 99 | BM108: 29 | BN108: 65 | BO108: 90 | BP108: 94 | BQ108: 63 | BR108: 22 | BS108: 80 | BT108: 29 | BU108: 79 | BV108: 18 | BW108: 51 | BX108: 39 | BY108: 64 | BZ108: 20 | CA108: 7 | CB108: 41 | CC108: 16 | CD108: 40 | CE108: 86 | CF108: 62 | CG108: 85 | CH108: 66 | CI108: 10 | CJ108: 77 | CK108: 56 | CL108: 25 | CM108: 1 | CN108: 19 | CO108: 6 | CP108: 50 | CQ108: 2 | CR108: 10 | CS108: 100 | CT108: 88 | CU108: 53 | CV108: 59
A109: 22 | B109: 100 | C109: 36 | D109: 57 | E109: 35 | F109: 76 | G109: 90 | H109: 40 | I109: 40 | J109: 73 | K109: 25 | L109: 71 | M109: 5 | N109: 51 | O109: 28 | P109: 61 | Q109: 51 | R109: 19 | S109: 37 | T109: 52 | U109: 72 | V109: 66 | W109: 86 | X109: 61 | Y109: 64 | Z109: 73 | AA109: 83 | AB109: 18 | AC109: 17 | AD109: 46 | AE109: 80 | AF109: 58 | AG109: 19 | AH109: 23 | AI109: 69 | AJ109: 8 | AK109: 20 | AL109: 5 | AM109: 76 | AN109: 20 | AO109: 3 | AP109: 59 | AQ109: 83 | AR109: 13 | AS109: 30 | AT109: 51 | AU109: 41 | AV109: 53 | AW109: 80 | AX109: 46 | AY109: 74 | AZ109: 19 | BA109: 77 | BB109: 12 | BC109: 62 | BD109: 51 | BE109: 88 | BF109: 45 | BG109: 14 | BH109: 77 | BI109: 40 | BJ109: 26 | BK109: 77 | BL109: 100 | BM109: 9 | BN109: 85 | BO109: 11 | BP109: 80 | BQ109: 67 | BR109: 61 | BS109: 85 | BT109: 2 | BU109: 98 | BV109: 46 | BW109: 22 | BX109: 100 | BY109: 80 | BZ109: 4 | CA109: 37 | CB109: 92 | CC109: 94 | CD109: 38 | CE109: 31 | CF109: 77 | CG109: 9 | CH109: 24 | CI109: 70 | CJ109: 38 | CK109: 80 | CL109: 100 | CM109: 22 | CN109: 11 | CO109: 26 | CP109: 23 | CQ109: 87 | CR109: 55 | CS109: 25 | CT109: 69 | CU109: 71 | CV109: 90
A110: 51 | B110: 22 | C110: 89 | D110: 49 | E110: 39 | F110: 79 | G110: 98 | H110: 7 | I110: 77 | J110: 82 | K110: 73 | L110: 6 | M110: 50 | N110: 17 | O110: 91 | P110: 53 | Q110: 97 | R110: 58 | S110: 27 | T110: 67 | U110: 19 | V110: 95 | W110: 28 | X110: 2 | Y110: 75 | Z110: 16 | AA110: 92 | AB110: 45 | AC110: 8 | AD110: 88 | AE110: 12 | AF110: 48 | AG110: 77 | AH110: 92 | AI110: 46 | AJ110: 25 | AK110: 12 | AL110: 58 | AM110: 34 | AN110: 92 | AO110: 71 | AP110: 57 | AQ110: 43 | AR110: 67 | AS110: 29 | AT110: 85 | AU110: 72 | AV110: 9 | AW110: 57 | AX110: 13 | AY110: 17 | AZ110: 34 | BA110: 21 | BB110: 66 | BC110: 19 | BD110: 44 | BE110: 3 | BF110: 56 | BG110: 90 | BH110: 73 | BI110: 90 | BJ110: 41 | BK110: 6 | BL110: 2 | BM110: 44 | BN110: 22 | BO110: 31 | BP110: 35 | BQ110: 72 | BR110: 43 | BS110: 87 | BT110: 43 | BU110: 19 | BV110: 54 | BW110: 91 | BX110: 70 | BY110: 61 | BZ110: 75 | CA110: 7 | CB110: 70 | CC110: 27 | CD110: 21 | CE110: 57 | CF110: 19 | CG110: 14 | CH110: 11 | CI110: 47 | CJ110: 47 | CK110: 33 | CL110: 42 | CM110: 55 | CN110: 59 | CO110: 53 | CP110: 56 | CQ110: 33 | CR110: 61 | CS110: 74 | CT110: 55 | CU110: 70 | CV110: 82
A111: 33 | B111: 71 | C111: 8 | D111: 34 | E111: 22 | F111: 97 | G111: 29 | H111: 15 | I111: 38 | J111: 4 | K111: 97 | L111: 82 | M111: 4 | N111: 81 | O111: 29 | P111: 60 | Q111: 9 | R111: 63 | S111: 24 | T111: 71 | U111: 87 | V111: 69 | W111: 3 | X111: 16 | Y111: 74 | Z111: 88 | AA111: 60 | AB111: 38 | AC111: 20 | AD111: 79 | AE111: 91 | AF111: 10 | AG111: 90 | AH111: 14 | AI111: 30 | AJ111: 10 | AK111: 3 | AL111: 40 | AM111: 58 | AN111: 19 | AO111: 74 | AP111: 84 | AQ111: 28 | AR111: 7 | AS111: 84 | AT111: 73 | AU111: 61 | AV111: 38 | AW111: 58 | AX111: 100 | AY111: 56 | AZ111: 62 | BA111: 7 | BB111: 48 | BC111: 5 | BD111: 84 | BE111: 63 | BF111: 85 | BG111: 45 | BH111: 22 | BI111: 8 | BJ111: 93 | BK111: 48 | BL111: 75 | BM111: 68 | BN111: 91 | BO111: 9 | BP111: 46 | BQ111: 7 | BR111: 7 | BS111: 71 | BT111: 28 | BU111: 94 | BV111: 60 | BW111: 43 | BX111: 91 | BY111: 91 | BZ111: 84 | CA111: 81 | CB111: 49 | CC111: 36 | CD111: 36 | CE111: 68 | CF111: 36 | CG111: 35 | CH111: 52 | CI111: 50 | CJ111: 47 | CK111: 48 | CL111: 96 | CM111: 69 | CN111: 100 | CO111: 94 | CP111: 39 | CQ111: 60 | CR111: 59 | CS111: 40 | CT111: 39 | CU111: 45 | CV111: 73
A112: 94 | B112: 16 | C112: 44 | D112: 54 | E112: 87 | F112: 24 | G112: 84 | H112: 15 | I112: 10 | J112: 84 | K112: 9 | L112: 99 | M112: 11 | N112: 24 | O112: 85 | P112: 80 | Q112: 54 | R112: 65 | S112: 97 | T112: 22 | U112: 86 | V112: 77 | W112: 61 | X112: 93 | Y112: 35 | Z112: 14 | AA112: 69 | AB112: 87 | AC112: 77 | AD112: 92 | AE112: 35 | AF112: 14 | AG112: 18 | AH112: 42 | AI112: 83 | AJ112: 81 | AK112: 59 | AL112: 98 | AM112: 38 | AN112: 52 | AO112: 65 | AP112: 73 | AQ112: 56 | AR112: 97 | AS112: 20 | AT112: 60 | AU112: 48 | AV112: 14 | AW112: 94 | AX112: 23 | AY112: 37 | AZ112: 89 | BA112: 24 | BB112: 14 | BC112: 43 | BD112: 49 | BE112: 11 | BF112: 30 | BG112: 71 | BH112: 17 | BI112: 34 | BJ112: 24 | BK112: 87 | BL112: 15 | BM112: 74 | BN112: 59 | BO112: 32 | BP112: 72 | BQ112: 42 | BR112: 72 | BS112: 23 | BT112: 42 | BU112: 68 | BV112: 72 | BW112: 29 | BX112: 7 | BY112: 74 | BZ112: 55 | CA112: 71 | CB112: 5 | CC112: 100 | CD112: 68 | CE112: 74 | CF112: 46 | CG112: 21 | CH112: 82 | CI112: 63 | CJ112: 56 | CK112: 6 | CL112: 23 | CM112: 4 | CN112: 6 | CO112: 74 | CP112: 5 | CQ112: 80 | CR112: 67 | CS112: 94 | CT112: 30 | CU112: 30 | CV112: 54
A113: 96 | B113: 67 | C113: 35 | D113: 85 | E113: 7 | F113: 43 | G113: 64 | H113: 26 | I113: 54 | J113: 35 | K113: 25 | L113: 18 | M113: 47 | N113: 75 | O113: 58 | P113: 42 | Q113: 19 | R113: 83 | S113: 45 | T113: 28 | U113: 45 | V113: 31 | W113: 85 | X113: 60 | Y113: 49 | Z113: 27 | AA113: 79 | AB113: 21 | AC113: 15 | AD113: 1 | AE113: 51 | AF113: 66 | AG113: 91 | AH113: 16 | AI113: 77 | AJ113: 47 | AK113: 5 | AL113: 72 | AM113: 62 | AN113: 49 | AO113: 56 | AP113: 46 | AQ113: 9 | AR113: 96 | AS113: 36 | AT113: 12 | AU113: 45 | AV113: 57 | AW113: 16 | AX113: 4 | AY113: 49 | AZ113: 77 | BA113: 60 | BB113: 55 | BC113: 89 | BD113: 59 | BE113: 32 | BF113: 74 | BG113: 89 | BH113: 31 | BI113: 68 | BJ113: 99 | BK113: 7 | BL113: 6 | BM113: 89 | BN113: 80 | BO113: 57 | BP113: 9 | BQ113: 37 | BR113: 68 | BS113: 27 | BT113: 61 | BU113: 16 | BV113: 75 | BW113: 45 | BX113: 39 | BY113: 9 | BZ113: 43 | CA113: 70 | CB113: 57 | CC113: 39 | CD113: 52 | CE113: 30 | CF113: 19 | CG113: 8 | CH113: 29 | CI113: 77 | CJ113: 95 | CK113: 76 | CL113: 6 | CM113: 96 | CN113: 69 | CO113: 18 | CP113: 67 | CQ113: 35 | CR113: 8 | CS113: 26 | CT113: 52 | CU113: 79 | CV113: 6
A114: 22 | B114: 98 | C114: 1 | D114: 3 | E114: 6 | F114: 94 | G114: 30 | H114: 54 | I114: 89 | J114: 63 | K114: 57 | L114: 18 | M114: 8 | N114: 9 | O114: 95 | P114: 31 | Q114: 98 | R114: 31 | S114: 1 | T114: 19 | U114: 96 | V114: 88 | W114: 22 | X114: 38 | Y114: 86 | Z114: 77 | AA114: 16 | AB114: 56 | AC114: 55 | AD114: 70 | AE114: 94 | AF114: 13 | AG114: 93 | AH114: 77 | AI114: 49 | AJ114: 35 | AK114: 2 | AL114: 58 | AM114: 2 | AN114: 27 | AO114: 53 | AP114: 67 | AQ114: 34 | AR114: 8 | AS114: 45 | AT114: 42 | AU114: 36 | AV114: 38 | AW114: 17 | AX114: 28 | AY114: 42 | AZ114: 65 | BA114: 36 | BB114: 59 | BC114: 6 | BD114: 82 | BE114: 3 | BF114: 5 | BG114: 78 | BH114: 27 | BI114: 25 | BJ114: 17 | BK114: 59 | BL114: 15 | BM114: 1 | BN114: 7 | BO114: 91 | BP114: 90 | BQ114: 70 | BR114: 84 | BS114: 91 | BT114: 57 | BU114: 34 | BV114: 76 | BW114: 69 | BX114: 97 | BY114: 72 | BZ114: 55 | CA114: 70 | CB114: 20 | CC114: 15 | CD114: 28 | CE114: 80 | CF114: 7 | CG114: 21 | CH114: 45 | CI114: 77 | CJ114: 90 | CK114: 88 | CL114: 63 | CM114: 40 | CN114: 22 | CO114: 85 | CP114: 27 | CQ114: 92 | CR114: 75 | CS114: 19 | CT114: 12 | CU114: 18 | CV114: 42
A115: 88 | B115: 72 | C115: 37 | D115: 62 | E115: 4 | F115: 60 | G115: 64 | H115: 48 | I115: 40 | J115: 24 | K115: 100 | L115: 26 | M115: 35 | N115: 97 | O115: 41 | P115: 85 | Q115: 35 | R115: 72 | S115: 83 | T115: 77 | U115: 31 | V115: 64 | W115: 49 | X115: 65 | Y115: 45 | Z115: 93 | AA115: 100 | AB115: 2 | AC115: 30 | AD115: 29 | AE115: 83 | AF115: 8 | AG115: 20 | AH115: 62 | AI115: 46 | AJ115: 91 | AK115: 82 | AL115: 33 | AM115: 96 | AN115: 54 | AO115: 35 | AP115: 87 | AQ115: 28 | AR115: 51 | AS115: 56 | AT115: 91 | AU115: 88 | AV115: 37 | AW115: 59 | AX115: 72 | AY115: 52 | AZ115: 98 | BA115: 8 | BB115: 18 | BC115: 46 | BD115: 21 | BE115: 38 | BF115: 71 | BG115: 74 | BH115: 8 | BI115: 95 | BJ115: 60 | BK115: 37 | BL115: 44 | BM115: 95 | BN115: 95 | BO115: 92 | BP115: 4 | BQ115: 1 | BR115: 36 | BS115: 41 | BT115: 57 | BU115: 70 | BV115: 8 | BW115: 32 | BX115: 91 | BY115: 31 | BZ115: 60 | CA115: 37 | CB115: 26 | CC115: 61 | CD115: 31 | CE115: 34 | CF115: 44 | CG115: 94 | CH115: 73 | CI115: 60 | CJ115: 12 | CK115: 34 | CL115: 68 | CM115: 86 | CN115: 19 | CO115: 93 | CP115: 12 | CQ115: 45 | CR115: 2 | CS115: 33 | CT115: 88 | CU115: 89 | CV115: 94
A116: 51 | B116: 69 | C116: 99 | D116: 90 | E116: 78 | F116: 67 | G116: 58 | H116: 80 | I116: 18 | J116: 85 | K116: 33 | L116: 1 | M116: 71 | N116: 41 | O116: 22 | P116: 24 | Q116: 63 | R116: 74 | S116: 21 | T116: 90 | U116: 82 | V116: 49 | W116: 74 | X116: 63 | Y116: 1 | Z116: 18 | AA116: 29 | AB116: 53 | AC116: 31 | AD116: 67 | AE116: 53 | AF116: 57 | AG116: 58 | AH116: 19 | AI116: 54 | AJ116: 78 | AK116: 17 | AL116: 23 | AM116: 64 | AN116: 56 | AO116: 42 | AP116: 94 | AQ116: 28 | AR116: 73 | AS116: 59 | AT116: 49 | AU116: 50 | AV116: 85 | AW116: 51 | AX116: 87 | AY116: 23 | AZ116: 62 | BA116: 12 | BB116: 9 | BC116: 34 | BD116: 27 | BE116: 60 | BF116: 68 | BG116: 99 | BH116: 62 | BI116: 81 | BJ116: 45 | BK116: 36 | BL116: 19 | BM116: 76 | BN116: 77 | BO116: 83 | BP116: 94 | BQ116: 56 | BR116: 73 | BS116: 86 | BT116: 99 | BU116: 55 | BV116: 28 | BW116: 66 | BX116: 33 | BY116: 66 | BZ116: 62 | CA116: 16 | CB116: 99 | CC116: 14 | CD116: 22 | CE116: 80 | CF116: 7 | CG116: 53 | CH116: 9 | CI116: 68 | CJ116: 31 | CK116: 9 | CL116: 67 | CM116: 47 | CN116: 54 | CO116: 31 | CP116: 100 | CQ116: 65 | CR116: 56 | CS116: 5 | CT116: 49 | CU116: 59 | CV116: 2
A117: 61 | B117: 3 | C117: 61 | D117: 65 | E117: 67 | F117: 21 | G117: 36 | H117: 83 | I117: 30 | J117: 93 | K117: 93 | L117: 32 | M117: 21 | N117: 46 | O117: 52 | P117: 40 | Q117: 71 | R117: 41 | S117: 1 | T117: 29 | U117: 42 | V117: 84 | W117: 57 | X117: 99 | Y117: 36 | Z117: 49 | AA117: 81 | AB117: 37 | AC117: 84 | AD117: 38 | AE117: 8 | AF117: 7 | AG117: 77 | AH117: 50 | AI117: 41 | AJ117: 48 | AK117: 80 | AL117: 91 | AM117: 48 | AN117: 64 | AO117: 84 | AP117: 89 | AQ117: 29 | AR117: 24 | AS117: 42 | AT117: 53 | AU117: 88 | AV117: 42 | AW117: 46 | AX117: 31 | AY117: 44 | AZ117: 36 | BA117: 38 | BB117: 12 | BC117: 12 | BD117: 42 | BE117: 87 | BF117: 71 | BG117: 91 | BH117: 16 | BI117: 72 | BJ117: 84 | BK117: 91 | BL117: 67 | BM117: 82 | BN117: 30 | BO117: 73 | BP117: 13 | BQ117: 20 | BR117: 83 | BS117: 6 | BT117: 20 | BU117: 88 | BV117: 31 | BW117: 5 | BX117: 14 | BY117: 80 | BZ117: 11 | CA117: 80 | CB117: 41 | CC117: 10 | CD117: 94 | CE117: 62 | CF117: 8 | CG117: 44 | CH117: 92 | CI117: 54 | CJ117: 50 | CK117: 81 | CL117: 13 | CM117: 48 | CN117: 96 | CO117: 24 | CP117: 34 | CQ117: 70 | CR117: 60 | CS117: 5 | CT117: 30 | CU117: 96 | CV117: 16
... A205: 91 | B205: 42 | C205: 11 | D205: 10 | E205: 42 | F205: 11 | G205: 11 | H205: 22 | I205: 2 | J205: 53 | K205: 39 | L205: 16 | M205: 24 | N205: 44 | O205: 98 | P205: 98 | Q205: 28 | R205: 14 | S205: 40 | T205: 86 | U205: 56 | V205: 92 | W205: 93 | X205: 4 | Y205: 41 | Z205: 30 | AA205: 29 | AB205: 94 | AC205: 34 | AD205: 47 | AE205: 13 | AF205: 59 | AG205: 42 | AH205: 46 | AI205: 99 | AJ205: 18 | AK205: 32 | AL205: 63 | AM205: 97 | AN205: 1 | AO205: 41 | AP205: 74 | AQ205: 90 | AR205: 48 | AS205: 50 | AT205: 46 | AU205: 31 | AV205: 53 | AW205: 68 | AX205: 41 | AY205: 50 | AZ205: 48 | BA205: 28 | BB205: 57 | BC205: 61 | BD205: 1 | BE205: 36 | BF205: 71 | BG205: 26 | BH205: 27 | BI205: 68 | BJ205: 38 | BK205: 20 | BL205: 42 | BM205: 55 | BN205: 26 | BO205: 91 | BP205: 96 | BQ205: 38 | BR205: 78 | BS205: 36 | BT205: 91 | BU205: 5 | BV205: 57 | BW205: 21 | BX205: 61 | BY205: 8 | BZ205: 69 | CA205: 97 | CB205: 59 | CC205: 96 | CD205: 30 | CE205: 70 | CF205: 3 | CG205: 26 | CH205: 9 | CI205: 59 | CJ205: 38 | CK205: 91 | CL205: 8 | CM205: 11 | CN205: 49 | CO205: 21 | CP205: 31 | CQ205: 5 | CR205: 87 | CS205: 13 | CT205: 83 | CU205: 8 | CV205: 62

Sheet (StratS index)
A1: =COUNTIF(A3:A102,"<=44") -> 44 | B1: =COUNTIF(B3:B102,"<=44") -> 44 | C1: =COUNTIF(C3:C102,"<=44") -> 44 | D1: =COUNTIF(D3:D102,"<=44") -> 44 | E1: =COUNTIF(E3:E102,"<=44") -> 44 | F1: =COUNTIF(F3:F102,"<=44") -> 44 | G1: =COUNTIF(G3:G102,"<=44") -> 44 | H1: =COUNTIF(H3:H102,"<=44") -> 44 | ... CV1: =COUNTIF(CV3:CV102,"<=44") -> 44
A2: Group A index | K2: Group A index | U2: Group A index | AE2: Group A index | AO2: Group A index | AY2: Group A index | BI2: Group A index | BS2: Group A index | CC2: Group A index | CM2: Group A index
A3: 23 | B3: 28 | C3: 19 | D3: 17 | E3: 44 | F3: 33 | G3: 17 | H3: 14 | I3: 19 | J3: 43 | K3: 7 | L3: 8 | M3: 15 | N3: 28 | O3: 8 | P3: 1 | Q3: 21 | R3: 26 | S3: 39 | T3: 8 | U3: 6 | V3: 37 | W3: 12 | X3: 34 | Y3: 9 | Z3: 40 | AA3: 16 | AB3: 39 | AC3: 3 | AD3: 7 | AE3: 36 | AF3: 6 | AG3: 43 | AH3: 33 | AI3: 7 | AJ3: 13 | AK3: 21 | AL3: 30 | AM3: 19 | AN3: 40 | AO3: 9 | AP3: 25 | AQ3: 17 | AR3: 2 | AS3: 31 | AT3: 13 | AU3: 44 | AV3: 15 | AW3: 33 | AX3: 17 | AY3: 32 | AZ3: 29 | BA3: 26 | BB3: 23 | BC3: 36 | BD3: 24 | BE3: 30 | BF3: 26 | BG3: 28 | BH3: 1 | BI3: 16 | BJ3: 32 | BK3: 41 | BL3: 7 | BM3: 5 | BN3: 10 | BO3: 41 | BP3: 9 | BQ3: 26 | BR3: 12 | BS3: 33 | BT3: 10 | BU3: 18 | BV3: 19 | BW3: 16 | BX3: 21 | BY3: 26 | BZ3: 10 | CA3: 43 | CB3: 12 | CC3: 31 | CD3: 9 | CE3: 37 | CF3: 24 | CG3: 40 | CH3: 10 | CI3: 29 | CJ3: 37 | CK3: 19 | CL3: 12 | CM3: 18 | CN3: 6 | CO3: 5 | CP3: 19 | CQ3: 26 | CR3: 2 | CS3: 15 | CT3: 16 | CU3: 44 | CV3: 34
A4: 41 | B4: 18 | C4: 11 | D4: 28 | E4: 3 | F4: 44 | G4: 3 | H4: 10 | I4: 27 | J4: 42 | K4: 9 | L4: 20 | M4: 21 | N4: 29 | O4: 27 | P4: 26 | Q4: 7 | R4: 17 | S4: 14 | T4: 40 | U4: 28 | V4: 10 | W4: 17 | X4: 2 | Y4: 39 | Z4: 41 | AA4: 2 | AB4: 12 | AC4: 20 | AD4: 36 | AE4: 44 | AF4: 19 | AG4: 35 | AH4: 25 | AI4: 35 | AJ4: 25 | AK4: 28 | AL4: 11 | AM4: 15 | AN4: 16 | AO4: 44 | AP4: 1 | AQ4: 25 | AR4: 21 | AS4: 17 | AT4: 8 | AU4: 8 | AV4: 13 | AW4: 22 | AX4: 40 | AY4: 28 | AZ4: 37 | BA4: 9 | BB4: 16 | BC4: 6 | BD4: 2 | BE4: 3 | BF4: 16 | BG4: 32 | BH4: 5 | BI4: 1 | BJ4: 20 | BK4: 33 | BL4: 16 | BM4: 27 | BN4: 31 | BO4: 5 | BP4: 6 | BQ4: 23 | BR4: 33 | BS4: 43 | BT4: 2 | BU4: 22 | BV4: 23 | BW4: 13 | BX4: 15 | BY4: 31 | BZ4: 17 | CA4: 35 | CB4: 40 | CC4: 15 | CD4: 37 | CE4: 31 | CF4: 41 | CG4: 34 | CH4: 29 | CI4: 5 | CJ4: 19 | CK4: 43 | CL4: 28 | CM4: 35 | CN4: 22 | CO4: 11 | CP4: 30 | CQ4: 42 | CR4: 13 | CS4: 28 | CT4: 28 | CU4: 12 | CV4: 38
A5: 35 | B5: 2 | C5: 41 | D5: 16 | E5: 27 | F5: 26 | G5: 34 | H5: 40 | I5: 10 | J5: 23 | K5: 42 | L5: 33 | M5: 37 | N5: 14 | O5: 13 | P5: 25 | Q5: 42 | R5: 27 | S5: 6 | T5: 28 | U5: 11 | V5: 8 | W5: 33 | X5: 32 | Y5: 32 | Z5: 7 | AA5: 6 | AB5: 34 | AC5: 8 | AD5: 44 | AE5: 20 | AF5: 6 | AG5: 33 | AH5: 18 | AI5: 35 | AJ5: 21 | AK5: 3 | AL5: 4 | AM5: 34 | AN5: 20 | AO5: 16 | AP5: 27 | AQ5: 17 | AR5: 37 | AS5: 11 | AT5: 40 | AU5: 27 | AV5: 25 | AW5: 11 | AX5: 40 | AY5: 16 | AZ5: 7 | BA5: 10 | BB5: 1 | BC5: 8 | BD5: 3 | BE5: 26 | BF5: 19 | BG5: 9 | BH5: 24 | BI5: 4 | BJ5: 18 | BK5: 44 | BL5: 6 | BM5: 34 | BN5: 26 | BO5: 24 | BP5: 40 | BQ5: 11 | BR5: 39 | BS5: 6 | BT5: 19 | BU5: 9 | BV5: 34 | BW5: 23 | BX5: 5 | BY5: 14 | BZ5: 38 | CA5: 34 | CB5: 24 | CC5: 12 | CD5: 5 | CE5: 22 | CF5: 14 | CG5: 15 | CH5: 12 | CI5: 38 | CJ5: 20 | CK5: 35 | CL5: 30 | CM5: 38 | CN5: 31 | CO5: 10 | CP5: 36 | CQ5: 12 | CR5: 14 | CS5: 23 | CT5: 33 | CU5: 7 | CV5: 19
A6: 19 | B6: 24 | C6: 9 | D6: 22 | E6: 33 | F6: 4 | G6: 19 | H6: 42 | I6: 42 | J6: 20 | K6: 5 | L6: 25 | M6: 44 | N6: 4 | O6: 42 | P6: 23 | Q6: 29 | R6: 7 | S6: 7 | T6: 24 | U6: 8 | V6: 23 | W6: 28 | X6: 37 | Y6: 14 | Z6: 35 | AA6: 8 | AB6: 3 | AC6: 30 | AD6: 21 | AE6: 4 | AF6: 38 | AG6: 35 | AH6: 40 | AI6: 35 | AJ6: 25 | AK6: 12 | AL6: 33 | AM6: 30 | AN6: 11 | AO6: 33 | AP6: 1 | AQ6: 12 | AR6: 7 | AS6: 43 | AT6: 29 | AU6: 18 | AV6: 16 | AW6: 28 | AX6: 33 | AY6: 29 | AZ6: 33 | BA6: 12 | BB6: 10 | BC6: 4 | BD6: 19 | BE6: 42 | BF6: 6 | BG6: 40 | BH6: 12 | BI6: 12 | BJ6: 24 | BK6: 33 | BL6: 1 | BM6: 31 | BN6: 44 | BO6: 26 | BP6: 17 | BQ6: 22 | BR6: 19 | BS6: 17 | BT6: 35 | BU6: 4 | BV6: 38 | BW6: 24 | BX6: 8 | BY6: 30 | BZ6: 15 | CA6: 35 | CB6: 16 | CC6: 26 | CD6: 38 | CE6: 3 | CF6: 17 | CG6: 37 | CH6: 20 | CI6: 35 | CJ6: 25 | CK6: 8 | CL6: 4 | CM6: 6 | CN6: 25 | CO6: 30 | CP6: 4 | CQ6: 28 | CR6: 40 | CS6: 30 | CT6: 2 | CU6: 40 | CV6: 34
A7: 28 | B7: 7 | C7: 16 | D7: 22 | E7: 5 | F7: 44 | G7: 23 | H7: 33 | I7: 21 | J7: 3 | K7: 1 | L7: 44 | M7: 19 | N7: 9 | O7: 12 | P7: 42 | Q7: 19 | R7: 22 | S7: 14 | T7: 1 | U7: 32 | V7: 33 | W7: 4 | X7: 17 | Y7: 5 | Z7: 20 | AA7: 35 | AB7: 14 | AC7: 37 | AD7: 11 | AE7: 18 | AF7: 26 | AG7: 44 | AH7: 38 | AI7: 4 | AJ7: 12 | AK7: 6 | AL7: 19 | AM7: 2 | AN7: 29 | AO7: 15 | AP7: 22 | AQ7: 4 | AR7: 17 | AS7: 19 | AT7: 11 | AU7: 30 | AV7: 41 | AW7: 42 | AX7: 17 | AY7: 29 | AZ7: 5 | BA7: 43 | BB7: 15 | BC7: 21 | BD7: 43 | BE7: 27 | BF7: 5 | BG7: 10 | BH7: 37 | BI7: 35 | BJ7: 21 | BK7: 43 | BL7: 28 | BM7: 16 | BN7: 30 | BO7: 42 | BP7: 14 | BQ7: 18 | BR7: 27 | BS7: 8 | BT7: 28 | BU7: 12 | BV7: 21 | BW7: 38 | BX7: 5 | BY7: 21 | BZ7: 39 | CA7: 5 | CB7: 7 | CC7: 19 | CD7: 21 | CE7: 23 | CF7: 20 | CG7: 3 | CH7: 44 | CI7: 11 | CJ7: 32 | CK7: 7 | CL7: 35 | CM7: 31 | CN7: 14 | CO7: 36 | CP7: 39 | CQ7: 29 | CR7: 23 | CS7: 18 | CT7: 19 | CU7: 18 | CV7: 28
A8: 5 | B8: 19 | C8: 20 | D8: 3 | E8: 29 | F8: 3 | G8: 6 | H8: 9 | I8: 13 | J8: 11 | K8: 9 | L8: 4 | M8: 36 | N8: 34 | O8: 31 | P8: 12 | Q8: 15 | R8: 36 | S8: 7 | T8: 26 | U8: 18 | V8: 9 | W8: 14 | X8: 18 | Y8: 34 | Z8: 33 | AA8: 6 | AB8: 9 | AC8: 18 | AD8: 1 | AE8: 2 | AF8: 20 | AG8: 12 | AH8: 33 | AI8: 14 | AJ8: 40 | AK8: 18 | AL8: 38 | AM8: 43 | AN8: 16 | AO8: 33 | AP8: 13 | AQ8: 27 | AR8: 28 | AS8: 6 | AT8: 6 | AU8: 31 | AV8: 7 | AW8: 4 | AX8: 33 | AY8: 5 | AZ8: 25 | BA8: 42 | BB8: 10 | BC8: 39 | BD8: 9 | BE8: 30 | BF8: 28 | BG8: 4 | BH8: 16 | BI8: 37 | BJ8: 39 | BK8: 13 | BL8: 26 | BM8: 24 | BN8: 7 | BO8: 38 | BP8: 33 | BQ8: 20 | BR8: 42 | BS8: 42 | BT8: 42 | BU8: 25 | BV8: 41 | BW8: 11 | BX8: 20 | BY8: 21 | BZ8: 7 | CA8: 25 | CB8: 15 | CC8: 42 | CD8: 6 | CE8: 4 | CF8: 9 | CG8: 14 | CH8: 16 | CI8: 14 | CJ8: 23 | CK8: 2 | CL8: 30 | CM8: 44 | CN8: 6 | CO8: 44 | CP8: 42 | CQ8: 26 | CR8: 17 | CS8: 11 | CT8: 34 | CU8: 24 | CV8: 15
A9: 3 | B9: 36 | C9: 39 | D9: 39 | E9: 32 | F9: 21 | G9: 44 | H9: 17 | I9: 5 | J9: 6 | K9: 38 | L9: 44 | M9: 14 | N9: 25 | O9: 24 | P9: 2 | Q9: 33 | R9: 10 | S9: 29 | T9: 35 | U9: 6 | V9: 6 | W9: 7 | X9: 16 | Y9: 44 | Z9: 36 | AA9: 11 | AB9: 8 | AC9: 24 | AD9: 13 | AE9: 25 | AF9: 11 | AG9: 34 | AH9: 3 | AI9: 19 | AJ9: 11 | AK9: 16 | AL9: 5 | AM9: 12 | AN9: 20 | AO9: 25 | AP9: 5 | AQ9: 11 | AR9: 16 | AS9: 37 | AT9: 17 | AU9: 43 | AV9: 4 | AW9: 29 | AX9: 5 | AY9: 25 | AZ9: 29 | BA9: 40 | BB9: 25 | BC9: 22 | BD9: 44 | BE9: 20 | BF9: 11 | BG9: 5 | BH9: 32 | BI9: 24 | BJ9: 7 | BK9: 34 | BL9: 32 | BM9: 3 | BN9: 7 | BO9: 26 | BP9: 23 | BQ9: 31 | BR9: 6 | BS9: 3 | BT9: 21 | BU9: 8 | BV9: 24 | BW9: 1 | BX9: 28 | BY9: 5 | BZ9: 29 | CA9: 27 | CB9: 24 | CC9: 6 | CD9: 4 | CE9: 25 | CF9: 29 | CG9: 25 | CH9: 9 | CI9: 19 | CJ9: 34 | CK9: 13 | CL9: 27 | CM9: 11 | CN9: 42 | CO9: 17 | CP9: 32 | CQ9: 8 | CR9: 22 | CS9: 30 | CT9: 15 | CU9: 14 | CV9: 24
A10: 9 | B10: 20 | C10: 2 | D10: 15 | E10: 11 | F10: 6 | G10: 21 | H10: 30 | I10: 42 | J10: 22 | K10: 20 | L10: 39 | M10: 3 | N10: 8 | O10: 37 | P10: 18 | Q10: 3 | R10: 15 | S10: 13 | T10: 42 | U10: 44 | V10: 33 | W10: 21 | X10: 2 | Y10: 40 | Z10: 40 | AA10: 42 | AB10: 30 | AC10: 35 | AD10: 26 | AE10: 9 | AF10: 39 | AG10: 13 | AH10: 14 | AI10: 6 | AJ10: 10 | AK10: 31 | AL10: 9 | AM10: 29 | AN10: 11 | AO10: 31 | AP10: 41 | AQ10: 44 | AR10: 41 | AS10: 27 | AT10: 42 | AU10: 28 | AV10: 39 | AW10: 13 | AX10: 32 | AY10: 21 | AZ10: 32 | BA10: 18 | BB10: 22 | BC10: 17 | BD10: 13 | BE10: 26 | BF10: 34 | BG10: 38 | BH10: 31 | BI10: 30 | BJ10: 22 | BK10: 18 | BL10: 25 | BM10: 7 | BN10: 1 | BO10: 29 | BP10: 42 | BQ10: 23 | BR10: 22 | BS10: 19 | BT10: 16 | BU10: 32 | BV10: 17 | BW10: 25 | BX10: 31 | BY10: 34 | BZ10: 7 | CA10: 24 | CB10: 5 | CC10: 13 | CD10: 4 | CE10: 42 | CF10: 32 | CG10: 14 | CH10: 25 | CI10: 32 | CJ10: 21 | CK10: 36 | CL10: 5 | CM10: 13 | CN10: 35 | CO10: 35 | CP10: 3 | CQ10: 20 | CR10: 8 | CS10: 38 | CT10: 2 | CU10: 5 | CV10: 34
A11: 6 | B11: 7 | C11: 8 | D11: 33 | E11: 24 | F11: 16 | G11: 35 | H11: 28 | I11: 40 | J11: 43 | K11: 28 | L11: 2 | M11: 28 | N11: 15 | O11: 20 | P11: 26 | Q11: 42 | R11: 16 | S11: 2 | T11: 7 | U11: 1 | V11: 43 | W11: 22 | X11: 3 | Y11: 37 | Z11: 12 | AA11: 32 | AB11: 17 | AC11: 8 | AD11: 6 | AE11: 7 | AF11: 40 | AG11: 20 | AH11: 23 | AI11: 31 | AJ11: 5 | AK11: 29 | AL11: 17 | AM11: 42 | AN11: 37 | AO11: 6 | AP11: 9 | AQ11: 23 | AR11: 41 | AS11: 21 | AT11: 38 | AU11: 33 | AV11: 28 | AW11: 10 | AX11: 25 | AY11: 16 | AZ11: 41 | BA11: 33 | BB11: 42 | BC11: 36 | BD11: 29 | BE11: 36 | BF11: 44 | BG11: 11 | BH11: 18 | BI11: 22 | BJ11: 24 | BK11: 15 | BL11: 22 | BM11: 31 | BN11: 13 | BO11: 31 | BP11: 24 | BQ11: 38 | BR11: 21 | BS11: 4 | BT11: 44 | BU11: 28 | BV11: 8 | BW11: 19 | BX11: 25 | BY11: 18 | BZ11: 5 | CA11: 15 | CB11: 18 | CC11: 38 | CD11: 5 | CE11: 24 | CF11: 7 | CG11: 30 | CH11: 9 | CI11: 44 | CJ11: 38 | CK11: 37 | CL11: 12 | CM11: 30 | CN11: 38 | CO11: 11 | CP11: 8 | CQ11: 6 | CR11: 8 | CS11: 7 | CT11: 36 | CU11: 32 | CV11: 6
A12: 22 | B12: 26 | C12: 39 | D12: 22 | E12: 1 | F12: 12 | G12: 25 | H12: 13 | I12: 23 | J12: 11 | K12: 33 | L12: 4 | M12: 3 | N12: 21 | O12: 43 | P12: 42 | Q12: 4 | R12: 5 | S12: 37 | T12: 12 | U12: 13 | V12: 41 | W12: 44 | X12: 26 | Y12: 4 | Z12: 35 | AA12: 16 | AB12: 32 | AC12: 28 | AD12: 17 | AE12: 1 | AF12: 22 | AG12: 31 | AH12: 12 | AI12: 10 | AJ12: 44 | AK12: 37 | AL12: 8 | AM12: 39 | AN12: 11 | AO12: 24 | AP12: 19 | AQ12: 17 | AR12: 15 | AS12: 28 | AT12: 40 | AU12: 40 | AV12: 14 | AW12: 35 | AX12: 37 | AY12: 42 | AZ12: 13 | BA12: 6 | BB12: 15 | BC12: 20 | BD12: 11 | BE12: 40 | BF12: 35 | BG12: 42 | BH12: 5 | BI12: 22 | BJ12: 32 | BK12: 27 | BL12: 32 | BM12: 11 | BN12: 33 | BO12: 4 | BP12: 39 | BQ12: 36 | BR12: 2 | BS12: 11 | BT12: 10 | BU12: 8 | BV12: 33 | BW12: 38 | BX12: 15 | BY12: 13 | BZ12: 38 | CA12: 4 | CB12: 30 | CC12: 16 | CD12: 13 | CE12: 40 | CF12: 29 | CG12: 30 | CH12: 8 | CI12: 15 | CJ12: 23 | CK12: 12 | CL12: 19 | CM12: 27 | CN12: 24 | CO12: 38 | CP12: 28 | CQ12: 10 | CR12: 38 | CS12: 41 | CT12: 2 | CU12: 40 | CV12: 31
A13: 12 | B13: 34 | C13: 30 | D13: 13 | E13: 22 | F13: 15 | G13: 9 | H13: 20 | I13: 22 | J13: 18 | K13: 36 | L13: 28 | M13: 37 | N13: 32 | O13: 24 | P13: 24 | Q13: 26 | R13: 32 | S13: 29 | T13: 26 | U13: 14 | V13: 35 | W13: 16 | X13: 10 | Y13: 28 | Z13: 40 | AA13: 4 | AB13: 1 | AC13: 13 | AD13: 12 | AE13: 33 | AF13: 1 | AG13: 32 | AH13: 14 | AI13: 23 | AJ13: 21 | AK13: 12 | AL13: 28 | AM13: 33 | AN13: 1 | AO13: 34 | AP13: 13 | AQ13: 12 | AR13: 17 | AS13: 39 | AT13: 1 | AU13: 38 | AV13: 10 | AW13: 29 | AX13: 43 | AY13: 10 | AZ13: 31 | BA13: 4 | BB13: 8 | BC13: 39 | BD13: 6 | BE13: 28 | BF13: 24 | BG13: 38 | BH13: 20 | BI13: 36 | BJ13: 34 | BK13: 2 | BL13: 27 | BM13: 41 | BN13: 26 | BO13: 18 | BP13: 36 | BQ13: 27 | BR13: 43 | BS13: 7 | BT13: 40 | BU13: 30 | BV13: 34 | BW13: 14 | BX13: 13 | BY13: 31 | BZ13: 8 | CA13: 19 | CB13: 8 | CC13: 43 | CD13: 32 | CE13: 39 | CF13: 12 | CG13: 9 | CH13: 4 | CI13: 3 | CJ13: 40 | CK13: 17 | CL13: 14 | CM13: 12 | CN13: 28 | CO13: 31 | CP13: 1 | CQ13: 20 | CR13: 41 | CS13: 20 | CT13: 42 | CU13: 30 | CV13: 36
A14: 29 | B14: 16 | C14: 4 | D14: 3 | E14: 5 | F14: 19 | G14: 24 | H14: 33 | I14: 23 | J14: 26 | K14: 31 | L14: 23 | M14: 32 | N14: 3 | O14: 32 | P14: 40 | Q14: 9 | R14: 30 | S14: 1 | T14: 13 | U14: 6 | V14: 16 | W14: 8 | X14: 11 | Y14: 18 | Z14: 9 | AA14: 6 | AB14: 38 | AC14: 2 | AD14: 24 | AE14: 43 | AF14: 11 | AG14: 29 | AH14: 37 | AI14: 3 | AJ14: 8 | AK14: 7 | AL14: 6 | AM14: 34 | AN14: 25 | AO14: 28 | AP14: 34 | AQ14: 14 | AR14: 11 | AS14: 23 | AT14: 17 | AU14: 20 | AV14: 28 | AW14: 31 | AX14: 11 | AY14: 12 | AZ14: 27 | BA14: 10 | BB14: 42 | BC14: 30 | BD14: 17 | BE14: 31 | BF14: 15 | BG14: 8 | BH14: 17 | BI14: 16 | BJ14: 39 | BK14: 3 | BL14: 14 | BM14: 42 | BN14: 6 | BO14: 11 | BP14: 11 | BQ14: 5 | BR14: 36 | BS14: 13 | BT14: 31 | BU14: 29 | BV14: 41 | BW14: 1 | BX14: 42 | BY14: 13 | BZ14: 19 | CA14: 27 | CB14: 8 | CC14: 15 | CD14: 42 | CE14: 41 | CF14: 40 | CG14: 38 | CH14: 8 | CI14: 26 | CJ14: 17 | CK14: 32 | CL14: 5 | CM14: 8 | CN14: 3 | CO14: 3 | CP14: 6 | CQ14: 7 | CR14: 6 | CS14: 33 | CT14: 1 | CU14: 41 | CV14: 6
... A102: 54 | B102: 90 | C102: 88 | D102: 85 | E102: 92 | F102: 78 | G102: 59 | H102: 88 | I102: 69 | J102: 67 | K102: 90 | L102: 79 | M102: 50 | N102: 100 | O102: 45 | P102: 96 | Q102: 83 | R102: 65 | S102: 49 | T102: 59 | U102: 88 | V102: 60 | W102: 56 | X102: 97 | Y102: 61 | Z102: 65 | AA102: 85 | AB102: 86 | AC102: 76 | AD102: 86 | AE102: 96 | AF102: 63 | AG102: 91 | AH102: 66 | AI102: 78 | AJ102: 84 | AK102: 51 | AL102: 87 | AM102: 55 | AN102: 62 | AO102: 82 | AP102: 62 | AQ102: 91 | AR102: 100 | AS102: 83 | AT102: 65 | AU102: 86 | AV102: 86 | AW102: 81 | AX102: 80 | AY102: 83 | AZ102: 66 | BA102: 97 | BB102: 59 | BC102: 91 | BD102: 95 | BE102: 49 | BF102: 72 | BG102: 73 | BH102: 87 | BI102: 53 | BJ102: 92 | BK102: 72 | BL102: 90 | BM102: 100 | BN102: 96 | BO102: 50 | BP102: 64 | BQ102: 71 | BR102: 83 | BS102: 96 | BT102: 78 | BU102: 77 | BV102: 68 | BW102: 59 | BX102: 66 | BY102: 79 | BZ102: 51 | CA102: 55 | CB102: 61 | CC102: 47 | CD102: 81 | CE102: 73 | CF102: 96 | CG102: 82 | CH102: 54 | CI102: 51 | CJ102: 84 | CK102: 67 | CL102: 72 | CM102: 59 | CN102: 91 | CO102: 57 | CP102: 81 | CQ102: 69 | CR102: 82 | CS102: 94 | CT102: 63 | CU102: 45 | CV102: 59
A104: =COUNTIF(A106:A205,"<=44") -> 44 | B104: =COUNTIF(B106:B205,"<=44") -> 44 | C104: =COUNTIF(C106:C205,"<=44") -> 44 | D104: =COUNTIF(D106:D205,"<=44") -> 44 | E104: =COUNTIF(E106:E205,"<=44") -> 44 | F104: =COUNTIF(F106:F205,"<=44") -> 44 | G104: =COUNTIF(G106:G205,"<=44") -> 44 | H104: =COUNTIF(H106:H205,"<=44") -> 44 | ... CV104: =COUNTIF(CV106:CV205,"<=44") -> 44
A105: Group B index | K105: Group B index | U105: Group B index | AE105: Group B index | AO105: Group B index | AY105: Group B index | BI105: Group B index | BS105: Group B index | CC105: Group B index | CM105: Group B index
A106: 16 | B106: 26 | C106: 35 | D106: 22 | E106: 18 | F106: 31 | G106: 24 | H106: 36 | I106: 24 | J106: 6 | K106: 18 | L106: 33 | M106: 14 | N106: 40 | O106: 7 | P106: 16 | Q106: 29 | R106: 1 | S106: 34 | T106: 38 | U106: 23 | V106: 12 | W106: 9 | X106: 14 | Y106: 38 | Z106: 7 | AA106: 21 | AB106: 1 | AC106: 2 | AD106: 23 | AE106: 30 | AF106: 30 | AG106: 18 | AH106: 28 | AI106: 11 | AJ106: 13 | AK106: 27 | AL106: 37 | AM106: 14 | AN106: 36 | AO106: 38 | AP106: 27 | AQ106: 12 | AR106: 24 | AS106: 2 | AT106: 6 | AU106: 9 | AV106: 16 | AW106: 34 | AX106: 19 | AY106: 39 | AZ106: 27 | BA106: 4 | BB106: 1 | BC106: 19 | BD106: 34 | BE106: 21 | BF106: 43 | BG106: 22 | BH106: 38 | BI106: 12 | BJ106: 25 | BK106: 11 | BL106: 30 | BM106: 12 | BN106: 14 | BO106: 32 | BP106: 30 | BQ106: 5 | BR106: 37 | BS106: 11 | BT106: 34 | BU106: 27 | BV106: 28 | BW106: 37 | BX106: 26 | BY106: 34 | BZ106: 2 | CA106: 43 | CB106: 39 | CC106: 40 | CD106: 9 | CE106: 15 | CF106: 15 | CG106: 23 | CH106: 32 | CI106: 31 | CJ106: 15 | CK106: 6 | CL106: 40 | CM106: 43 | CN106: 18 | CO106: 40 | CP106: 12 | CQ106: 16 | CR106: 19 | CS106: 7 | CT106: 36 | CU106: 33 | CV106: 26
A107: 2 | B107: 33 | C107: 8 | D107: 12 | E107: 18 | F107: 23 | G107: 9 | H107: 38 | I107: 27 | J107: 33 | K107: 34 | L107: 44 | M107: 36 | N107: 2 | O107: 39 | P107: 44 | Q107: 10 | R107: 20 | S107: 16 | T107: 25 | U107: 4 | V107: 22 | W107: 14 | X107: 29 | Y107: 23 | Z107: 1 | AA107: 10 | AB107: 18 | AC107: 10 | AD107: 2 | AE107: 18 | AF107: 5 | AG107: 28 | AH107: 20 | AI107: 10 | AJ107: 25 | AK107: 13 | AL107: 30 | AM107: 25 | AN107: 18 | AO107: 30 | AP107: 8 | AQ107: 6 | AR107: 30 | AS107: 3 | AT107: 42 | AU107: 1 | AV107: 27 | AW107: 40 | AX107: 35 | AY107: 3 | AZ107: 16 | BA107: 11 | BB107: 31 | BC107: 22 | BD107: 9 | BE107: 33 | BF107: 41 | BG107: 14 | BH107: 27 | BI107: 29 | BJ107: 11 | BK107: 3 | BL107: 31 | BM107: 15 | BN107: 29 | BO107: 13 | BP107: 30 | BQ107: 39 | BR107: 29 | BS107: 14 | BT107: 27 | BU107: 9 | BV107: 33 | BW107: 37 | BX107: 6 | BY107: 6 | BZ107: 19 | CA107: 32 | CB107: 27 | CC107: 8 | CD107: 27 | CE107: 30 | CF107: 6 | CG107: 9 | CH107: 14 | CI107: 9 | CJ107: 41 | CK107: 28 | CL107: 4 | CM107: 11 | CN107: 38 | CO107: 38 | CP107: 17 | CQ107: 7 | CR107: 1 | CS107: 40 | CT107: 36 | CU107: 27 | CV107: 22
A108: 37 | B108: 41 | C108: 19 | D108: 14 | E108: 24 | F108: 8 | G108: 9 | H108: 27 | I108: 19 | J108: 26 | K108: 22 | L108: 28 | M108: 19 | N108: 2 | O108: 39 | P108: 17 | Q108: 9 | R108: 34 | S108: 42 | T108: 7 | U108: 40 | V108: 19 | W108: 25 | X108: 13 | Y108: 7 | Z108: 35 | AA108: 26 | AB108: 28 | AC108: 26 | AD108: 1 | AE108: 20 | AF108: 42 | AG108: 28 | AH108: 15 | AI108: 16 | AJ108: 43 | AK108: 3 | AL108: 26 | AM108: 10 | AN108: 19 | AO108: 31 | AP108: 43 | AQ108: 7 | AR108: 35 | AS108: 32 | AT108: 34 | AU108: 41 | AV108: 43 | AW108: 10 | AX108: 7 | AY108: 32 | AZ108: 24 | BA108: 26 | BB108: 5 | BC108: 1 | BD108: 8 | BE108: 36 | BF108: 16 | BG108: 35 | BH108: 24 | BI108: 31 | BJ108: 16 | BK108: 28 | BL108: 12 | BM108: 11 | BN108: 19 | BO108: 21 | BP108: 24 | BQ108: 25 | BR108: 38 | BS108: 3 | BT108: 31 | BU108: 7 | BV108: 10 | BW108: 1 | BX108: 19 | BY108: 36 | BZ108: 22 | CA108: 32 | CB108: 43 | CC108: 32 | CD108: 24 | CE108: 31 | CF108: 4 | CG108: 11 | CH108: 23 | CI108: 2 | CJ108: 33 | CK108: 40 | CL108: 12 | CM108: 44 | CN108: 31 | CO108: 4 | CP108: 43 | CQ108: 37 | CR108: 3 | CS108: 37 | CT108: 32 | CU108: 42 | CV108: 9
A109: 24 | B109: 43 | C109: 36 | D109: 10 | E109: 9 | F109: 40 | G109: 19 | H109: 10 | I109: 40 | J109: 41 | K109: 2 | L109: 24 | M109: 39 | N109: 8 | O109: 34 | P109: 36 | Q109: 33 | R109: 6 | S109: 25 | T109: 44 | U109: 34 | V109: 41 | W109: 30 | X109: 9 | Y109: 12 | Z109: 3 | AA109: 4 | AB109: 6 | AC109: 27 | AD109: 27 | AE109: 2 | AF109: 20 | AG109: 9 | AH109: 39 | AI109: 38 | AJ109: 29 | AK109: 9 | AL109: 24 | AM109: 25 | AN109: 38 | AO109: 12 | AP109: 12 | AQ109: 38 | AR109: 4 | AS109: 44 | AT109: 36 | AU109: 3 | AV109: 24 | AW109: 10 | AX109: 24 | AY109: 8 | AZ109: 14 | BA109: 9 | BB109: 25 | BC109: 1 | BD109: 7 | BE109: 32 | BF109: 3 | BG109: 27 | BH109: 25 | BI109: 38 | BJ109: 21 | BK109: 15 | BL109: 2 | BM109: 36 | BN109: 35 | BO109: 28 | BP109: 26 | BQ109: 17 | BR109: 25 | BS109: 15 | BT109: 21 | BU109: 21 | BV109: 10 | BW109: 23 | BX109: 4 | BY109: 12 | BZ109: 2 | CA109: 4 | CB109: 10 | CC109: 19 | CD109: 19 | CE109: 33 | CF109: 16 | CG109: 44 | CH109: 32 | CI109: 38 | CJ109: 17 | CK109: 11 | CL109: 23 | CM109: 27 | CN109: 13 | CO109: 14 | CP109: 17 | CQ109: 44 | CR109: 18 | CS109: 31 | CT109: 7 | CU109: 9 | CV109: 22
A110: 18 | B110: 13 | C110: 21 | D110: 26 | E110: 42 | F110: 35 | G110: 15 | H110: 21 | I110: 23 | J110: 26 | K110: 17 | L110: 20 | M110: 8 | N110: 26 | O110: 25 | P110: 24 | Q110: 7 | R110: 28 | S110: 24 | T110: 28 | U110: 28 | V110: 24 | W110: 43 | X110: 3 | Y110: 29 | Z110: 20 | AA110: 16 | AB110: 36 | AC110: 3 | AD110: 4 | AE110: 33 | AF110: 3 | AG110: 14 | AH110: 23 | AI110: 8 | AJ110: 3 | AK110: 13 | AL110: 21 | AM110: 43 | AN110: 15 | AO110: 19 | AP110: 21 | AQ110: 23 | AR110: 23 | AS110: 13 | AT110: 21 | AU110: 7 | AV110: 8 | AW110: 34 | AX110: 2 | AY110: 19 | AZ110: 19 | BA110: 33 | BB110: 22 | BC110: 25 | BD110: 25 | BE110: 8 | BF110: 7 | BG110: 9 | BH110: 15 | BI110: 38 | BJ110: 37 | BK110: 13 | BL110: 20 | BM110: 19 | BN110: 17 | BO110: 17 | BP110: 24 | BQ110: 11 | BR110: 11 | BS110: 4 | BT110: 19 | BU110: 15 | BV110: 23 | BW110: 37 | BX110: 37 | BY110: 12 | BZ110: 29 | CA110: 36 | CB110: 22 | CC110: 8 | CD110: 29 | CE110: 13 | CF110: 22 | CG110: 23 | CH110: 9 | CI110: 43 | CJ110: 9 | CK110: 12 | CL110: 5 | CM110: 43 | CN110: 19 | CO110: 25 | CP110: 28 | CQ110: 24 | CR110: 43 | CS110: 40 | CT110: 4 | CU110: 25 | CV110: 31
A111: 12 | B111: 3 | C111: 33 | D111: 38 | E111: 8 | F111: 42 | G111: 14 | H111: 5 | I111: 28 | J111: 13 | K111: 12 | L111: 7 | M111: 4 | N111: 20 | O111: 31 | P111: 1 | Q111: 29 | R111: 34 | S111: 32 | T111: 40 | U111: 11 | V111: 7 | W111: 42 | X111: 33 | Y111: 23 | Z111: 28 | AA111: 1 | AB111: 37 | AC111: 38 | AD111: 8 | AE111: 8 | AF111: 38 | AG111: 6 | AH111: 10 | AI111: 10 | AJ111: 6 | AK111: 19 | AL111: 22 | AM111: 21 | AN111: 7 | AO111: 33 | AP111: 31 | AQ111: 38 | AR111: 20 | AS111: 24 | AT111: 18 | AU111: 18 | AV111: 35 | AW111: 4 | AX111: 34 | AY111: 21 | AZ111: 17 | BA111: 1 | BB111: 23 | BC111: 28 | BD111: 35 | BE111: 20 | BF111: 31 | BG111: 15 | BH111: 37 | BI111: 13 | BJ111: 36 | BK111: 38 | BL111: 34 | BM111: 11 | BN111: 25 | BO111: 24 | BP111: 44 | BQ111: 41 | BR111: 3 | BS111: 42 | BT111: 34 | BU111: 30 | BV111: 33 | BW111: 15 | BX111: 16 | BY111: 24 | BZ111: 22 | CA111: 16 | CB111: 22 | CC111: 36 | CD111: 33 | CE111: 27 | CF111: 1 | CG111: 39 | CH111: 28 | CI111: 35 | CJ111: 38 | CK111: 31 | CL111: 7 | CM111: 28 | CN111: 13 | CO111: 11 | CP111: 19 | CQ111: 8 | CR111: 23 | CS111: 41 | CT111: 39 | CU111: 9 | CV111: 21
A112: 2 | B112: 7 | C112: 10 | D112: 15 | E112: 14 | F112: 3 | G112: 24 | H112: 13 | I112: 32 | J112: 25 | K112: 14 | L112: 21 | M112: 3 | N112: 43 | O112: 22 | P112: 2 | Q112: 22 | R112: 18 | S112: 3 | T112: 32 | U112: 19 | V112: 42 | W112: 2 | X112: 9 | Y112: 34 | Z112: 12 | AA112: 44 | AB112: 8 | AC112: 37 | AD112: 8 | AE112: 36 | AF112: 21 | AG112: 38 | AH112: 30 | AI112: 29 | AJ112: 2 | AK112: 44 | AL112: 35 | AM112: 18 | AN112: 1 | AO112: 40 | AP112: 3 | AQ112: 20 | AR112: 23 | AS112: 43 | AT112: 37 | AU112: 21 | AV112: 27 | AW112: 42 | AX112: 42 | AY112: 44 | AZ112: 3 | BA112: 17 | BB112: 27 | BC112: 40 | BD112: 4 | BE112: 16 | BF112: 15 | BG112: 21 | BH112: 43 | BI112: 2 | BJ112: 11 | BK112: 26 | BL112: 36 | BM112: 23 | BN112: 17 | BO112: 16 | BP112: 43 | BQ112: 25 | BR112: 18 | BS112: 4 | BT112: 28 | BU112: 27 | BV112: 15 | BW112: 17 | BX112: 12 | BY112: 25 | BZ112: 21 | CA112: 36 | CB112: 43 | CC112: 40 | CD112: 31 | CE112: 32 | CF112: 36 | CG112: 32 | CH112: 31 | CI112: 16 | CJ112: 7 | CK112: 43 | CL112: 29 | CM112: 21 | CN112: 34 | CO112: 22 | CP112: 38 | CQ112: 1 | CR112: 3 | CS112: 23 | CT112: 34 | CU112: 16 | CV112: 8
